Traceback (most recent call last):
  File "/home/adry/final/csc376_final/client2/../ChatClient.py", line 348, in <module>
    main()
  File "/home/adry/final/csc376_final/client2/../ChatClient.py", line 342, in main
    client(port, address, connect_server_port)
  File "/home/adry/final/csc376_final/client2/../ChatClient.py", line 218, in client
    ui(sock, port, "client") 
    ^^^^^^^^^^^^^^^^^^^^^^^^
  File "/home/adry/final/csc376_final/client2/../ChatClient.py", line 276, in ui
    f_server(sock, port, filename) 
    ^^^^^^^^^^^^^^^^^^^^^^^^^^^^^^
  File "/home/adry/final/csc376_final/client2/../ChatClient.py", line 67, in f_server
    serversocket.bind(('localhost', port)) 
    ^^^^^^^^^^^^^^^^^^^^^^^^^^^^^^^^^^^^^^
OSError: [Errno 98] Address already in use
Exception in thread Thread-1 (receive):
Traceback (most recent call last):
  File "/usr/lib/python3.12/threading.py", line 1073, in _bootstrap_inner
    self.run()
  File "/usr/lib/python3.12/threading.py", line 1010, in run
    self._target(*self._args, **self._kwargs)
  File "/home/adry/final/csc376_final/client2/../ChatClient.py", line 96, in receive
    port_recv = decode_recv(sock)
                ^^^^^^^^^^^^^^^^^
  File "/home/adry/final/csc376_final/client2/../ChatClient.py", line 89, in decode_recv
    grab_port = int(split_bytes[0])
                ^^^^^^^^^^^^^^^^^^^
ValueError: invalid literal for int() with base 10: ''
Traceback (most recent call last):
  File "/home/adry/final/csc376_final/client2/../ChatClient.py", line 348, in <module>
    main()
  File "/home/adry/final/csc376_final/client2/../ChatClient.py", line 342, in main
    client(port, address, connect_server_port)
  File "/home/adry/final/csc376_final/client2/../ChatClient.py", line 218, in client
    ui(sock, port, "client") 
    ^^^^^^^^^^^^^^^^^^^^^^^^
  File "/home/adry/final/csc376_final/client2/../ChatClient.py", line 267, in ui
    sock.send(message.encode())
BrokenPipeError: [Errno 32] Broken pipe
